[2024-03-04T20:45:41.259+0000] {taskinstance.py:1956} INFO - Dependencies all met for dep_context=non-requeueable deps ti=<TaskInstance: Extraçao_de_dados_do_linkedin.Carregamento_dos_dados manual__2024-03-04T20:45:34.179693+00:00 [queued]>
[2024-03-04T20:45:41.270+0000] {taskinstance.py:1956} INFO - Dependencies all met for dep_context=requeueable deps ti=<TaskInstance: Extraçao_de_dados_do_linkedin.Carregamento_dos_dados manual__2024-03-04T20:45:34.179693+00:00 [queued]>
[2024-03-04T20:45:41.270+0000] {taskinstance.py:2170} INFO - Starting attempt 1 of 1
[2024-03-04T20:45:41.313+0000] {taskinstance.py:2191} INFO - Executing <Task(PythonOperator): Carregamento_dos_dados> on 2024-03-04 20:45:34.179693+00:00
[2024-03-04T20:45:41.319+0000] {standard_task_runner.py:60} INFO - Started process 1023 to run task
[2024-03-04T20:45:41.322+0000] {standard_task_runner.py:87} INFO - Running: ['***', 'tasks', 'run', 'Extraçao_de_dados_do_linkedin', 'Carregamento_dos_dados', 'manual__2024-03-04T20:45:34.179693+00:00', '--job-id', '27', '--raw', '--subdir', 'DAGS_FOLDER/dag_exemplo.py', '--cfg-path', '/tmp/tmpweua71fe']
[2024-03-04T20:45:41.324+0000] {standard_task_runner.py:88} INFO - Job 27: Subtask Carregamento_dos_dados
[2024-03-04T20:45:41.397+0000] {task_command.py:423} INFO - Running <TaskInstance: Extraçao_de_dados_do_linkedin.Carregamento_dos_dados manual__2024-03-04T20:45:34.179693+00:00 [running]> on host 43d6e1a41402
[2024-03-04T20:45:41.678+0000] {taskinstance.py:2480} INFO - Exporting env vars: AIRFLOW_CTX_DAG_OWNER='***' AIRFLOW_CTX_DAG_ID='Extraçao_de_dados_do_linkedin' AIRFLOW_CTX_TASK_ID='Carregamento_dos_dados' AIRFLOW_CTX_EXECUTION_DATE='2024-03-04T20:45:34.179693+00:00' AIRFLOW_CTX_TRY_NUMBER='1' AIRFLOW_CTX_DAG_RUN_ID='manual__2024-03-04T20:45:34.179693+00:00'
[2024-03-04T20:45:41.817+0000] {taskinstance.py:2698} ERROR - Task failed with exception
Traceback (most recent call last):
  File "/home/airflow/.local/lib/python3.8/site-packages/airflow/models/taskinstance.py", line 433, in _execute_task
    result = execute_callable(context=context, **execute_callable_kwargs)
  File "/home/airflow/.local/lib/python3.8/site-packages/airflow/operators/python.py", line 199, in execute
    return_value = self.execute_callable()
  File "/home/airflow/.local/lib/python3.8/site-packages/airflow/operators/python.py", line 216, in execute_callable
    return self.python_callable(*self.op_args, **self.op_kwargs)
  File "/opt/airflow/dags/dag_exemplo.py", line 247, in load_data
    dados.to_excel(destination_path, index=False)
  File "/home/airflow/.local/lib/python3.8/site-packages/pandas/core/generic.py", line 2252, in to_excel
    formatter.write(
  File "/home/airflow/.local/lib/python3.8/site-packages/pandas/io/formats/excel.py", line 934, in write
    writer = ExcelWriter(  # type: ignore[abstract]
  File "/home/airflow/.local/lib/python3.8/site-packages/pandas/io/excel/_openpyxl.py", line 56, in __init__
    from openpyxl.workbook import Workbook
ModuleNotFoundError: No module named 'openpyxl'
[2024-03-04T20:45:41.832+0000] {taskinstance.py:1138} INFO - Marking task as FAILED. dag_id=Extraçao_de_dados_do_linkedin, task_id=Carregamento_dos_dados, execution_date=20240304T204534, start_date=20240304T204541, end_date=20240304T204541
[2024-03-04T20:45:41.880+0000] {standard_task_runner.py:107} ERROR - Failed to execute job 27 for task Carregamento_dos_dados (No module named 'openpyxl'; 1023)
[2024-03-04T20:45:41.897+0000] {local_task_job_runner.py:234} INFO - Task exited with return code 1
[2024-03-04T20:45:41.910+0000] {taskinstance.py:3280} INFO - 0 downstream tasks scheduled from follow-on schedule check
