[2024-03-04T20:45:01.835+0000] {taskinstance.py:1956} INFO - Dependencies all met for dep_context=non-requeueable deps ti=<TaskInstance: Extraçao_de_dados_do_linkedin.Extraçao_dos_dados manual__2024-03-04T20:45:00.336634+00:00 [queued]>
[2024-03-04T20:45:01.844+0000] {taskinstance.py:1956} INFO - Dependencies all met for dep_context=requeueable deps ti=<TaskInstance: Extraçao_de_dados_do_linkedin.Extraçao_dos_dados manual__2024-03-04T20:45:00.336634+00:00 [queued]>
[2024-03-04T20:45:01.845+0000] {taskinstance.py:2170} INFO - Starting attempt 1 of 1
[2024-03-04T20:45:01.922+0000] {taskinstance.py:2191} INFO - Executing <Task(PythonOperator): Extraçao_dos_dados> on 2024-03-04 20:45:00.336634+00:00
[2024-03-04T20:45:01.964+0000] {standard_task_runner.py:60} INFO - Started process 1006 to run task
[2024-03-04T20:45:01.966+0000] {standard_task_runner.py:87} INFO - Running: ['***', 'tasks', 'run', 'Extraçao_de_dados_do_linkedin', 'Extraçao_dos_dados', 'manual__2024-03-04T20:45:00.336634+00:00', '--job-id', '24', '--raw', '--subdir', 'DAGS_FOLDER/dag_exemplo.py', '--cfg-path', '/tmp/tmppqqxqf9g']
[2024-03-04T20:45:01.969+0000] {standard_task_runner.py:88} INFO - Job 24: Subtask Extraçao_dos_dados
[2024-03-04T20:45:02.055+0000] {task_command.py:423} INFO - Running <TaskInstance: Extraçao_de_dados_do_linkedin.Extraçao_dos_dados manual__2024-03-04T20:45:00.336634+00:00 [running]> on host 43d6e1a41402
[2024-03-04T20:45:02.445+0000] {taskinstance.py:2480} INFO - Exporting env vars: AIRFLOW_CTX_DAG_OWNER='***' AIRFLOW_CTX_DAG_ID='Extraçao_de_dados_do_linkedin' AIRFLOW_CTX_TASK_ID='Extraçao_dos_dados' AIRFLOW_CTX_EXECUTION_DATE='2024-03-04T20:45:00.336634+00:00' AIRFLOW_CTX_TRY_NUMBER='1' AIRFLOW_CTX_DAG_RUN_ID='manual__2024-03-04T20:45:00.336634+00:00'
[2024-03-04T20:45:02.687+0000] {taskinstance.py:2698} ERROR - Task failed with exception
Traceback (most recent call last):
  File "/home/airflow/.local/lib/python3.8/site-packages/airflow/models/taskinstance.py", line 433, in _execute_task
    result = execute_callable(context=context, **execute_callable_kwargs)
  File "/home/airflow/.local/lib/python3.8/site-packages/airflow/operators/python.py", line 199, in execute
    return_value = self.execute_callable()
  File "/home/airflow/.local/lib/python3.8/site-packages/airflow/operators/python.py", line 216, in execute_callable
    return self.python_callable(*self.op_args, **self.op_kwargs)
  File "/opt/airflow/dags/dag_exemplo.py", line 39, in extract_and_save_data
    dados.to_csv(destination_path, index=False)
  File "/home/airflow/.local/lib/python3.8/site-packages/pandas/core/generic.py", line 3772, in to_csv
    return DataFrameRenderer(formatter).to_csv(
  File "/home/airflow/.local/lib/python3.8/site-packages/pandas/io/formats/format.py", line 1186, in to_csv
    csv_formatter.save()
  File "/home/airflow/.local/lib/python3.8/site-packages/pandas/io/formats/csvs.py", line 240, in save
    with get_handle(
  File "/home/airflow/.local/lib/python3.8/site-packages/pandas/io/common.py", line 737, in get_handle
    check_parent_directory(str(handle))
  File "/home/airflow/.local/lib/python3.8/site-packages/pandas/io/common.py", line 600, in check_parent_directory
    raise OSError(rf"Cannot save file into a non-existent directory: '{parent}'")
OSError: Cannot save file into a non-existent directory: '/opt/***/dags/results'
[2024-03-04T20:45:02.986+0000] {taskinstance.py:1138} INFO - Marking task as FAILED. dag_id=Extraçao_de_dados_do_linkedin, task_id=Extraçao_dos_dados, execution_date=20240304T204500, start_date=20240304T204501, end_date=20240304T204502
[2024-03-04T20:45:03.126+0000] {standard_task_runner.py:107} ERROR - Failed to execute job 24 for task Extraçao_dos_dados (Cannot save file into a non-existent directory: '/opt/***/dags/results'; 1006)
[2024-03-04T20:45:03.143+0000] {local_task_job_runner.py:234} INFO - Task exited with return code 1
[2024-03-04T20:45:03.224+0000] {taskinstance.py:3280} INFO - 0 downstream tasks scheduled from follow-on schedule check
