[2024-03-04T18:58:53.431+0000] {taskinstance.py:1956} INFO - Dependencies all met for dep_context=non-requeueable deps ti=<TaskInstance: Extraçao_de_dados_do_linkedin.Extraçao_dos_dados manual__2024-03-04T18:58:45.663283+00:00 [queued]>
[2024-03-04T18:58:53.439+0000] {taskinstance.py:1956} INFO - Dependencies all met for dep_context=requeueable deps ti=<TaskInstance: Extraçao_de_dados_do_linkedin.Extraçao_dos_dados manual__2024-03-04T18:58:45.663283+00:00 [queued]>
[2024-03-04T18:58:53.440+0000] {taskinstance.py:2170} INFO - Starting attempt 1 of 1
[2024-03-04T18:58:53.589+0000] {taskinstance.py:2191} INFO - Executing <Task(BashOperator): Extraçao_dos_dados> on 2024-03-04 18:58:45.663283+00:00
[2024-03-04T18:58:53.677+0000] {standard_task_runner.py:60} INFO - Started process 705 to run task
[2024-03-04T18:58:53.683+0000] {standard_task_runner.py:87} INFO - Running: ['***', 'tasks', 'run', 'Extraçao_de_dados_do_linkedin', 'Extraçao_dos_dados', 'manual__2024-03-04T18:58:45.663283+00:00', '--job-id', '5', '--raw', '--subdir', 'DAGS_FOLDER/dag_exemplo.py', '--cfg-path', '/tmp/tmpu3jv5nql']
[2024-03-04T18:58:53.688+0000] {standard_task_runner.py:88} INFO - Job 5: Subtask Extraçao_dos_dados
[2024-03-04T18:58:53.832+0000] {task_command.py:423} INFO - Running <TaskInstance: Extraçao_de_dados_do_linkedin.Extraçao_dos_dados manual__2024-03-04T18:58:45.663283+00:00 [running]> on host 46342418dab4
[2024-03-04T18:58:54.128+0000] {taskinstance.py:2480} INFO - Exporting env vars: AIRFLOW_CTX_DAG_OWNER='***' AIRFLOW_CTX_DAG_ID='Extraçao_de_dados_do_linkedin' AIRFLOW_CTX_TASK_ID='Extraçao_dos_dados' AIRFLOW_CTX_EXECUTION_DATE='2024-03-04T18:58:45.663283+00:00' AIRFLOW_CTX_TRY_NUMBER='1' AIRFLOW_CTX_DAG_RUN_ID='manual__2024-03-04T18:58:45.663283+00:00'
[2024-03-04T18:58:54.146+0000] {subprocess.py:63} INFO - Tmp dir root location: /tmp
[2024-03-04T18:58:54.147+0000] {subprocess.py:75} INFO - Running command: ['/usr/bin/bash', '-c', 'uvicorn dags.app:app --reload']
[2024-03-04T18:58:54.195+0000] {subprocess.py:86} INFO - Output:
[2024-03-04T18:58:54.305+0000] {subprocess.py:93} INFO - /usr/bin/bash: line 1: uvicorn: command not found
[2024-03-04T18:58:54.306+0000] {subprocess.py:97} INFO - Command exited with return code 127
[2024-03-04T18:58:54.319+0000] {taskinstance.py:2698} ERROR - Task failed with exception
Traceback (most recent call last):
  File "/home/airflow/.local/lib/python3.8/site-packages/airflow/models/taskinstance.py", line 433, in _execute_task
    result = execute_callable(context=context, **execute_callable_kwargs)
  File "/home/airflow/.local/lib/python3.8/site-packages/airflow/operators/bash.py", line 212, in execute
    raise AirflowException(
airflow.exceptions.AirflowException: Bash command failed. The command returned a non-zero exit code 127.
[2024-03-04T18:58:54.366+0000] {taskinstance.py:1138} INFO - Marking task as FAILED. dag_id=Extraçao_de_dados_do_linkedin, task_id=Extraçao_dos_dados, execution_date=20240304T185845, start_date=20240304T185853, end_date=20240304T185854
[2024-03-04T18:58:54.469+0000] {standard_task_runner.py:107} ERROR - Failed to execute job 5 for task Extraçao_dos_dados (Bash command failed. The command returned a non-zero exit code 127.; 705)
[2024-03-04T18:58:54.497+0000] {local_task_job_runner.py:234} INFO - Task exited with return code 1
[2024-03-04T18:58:54.510+0000] {taskinstance.py:3280} INFO - 0 downstream tasks scheduled from follow-on schedule check
