[2024-03-06T02:22:48.380+0000] {taskinstance.py:1956} INFO - Dependencies all met for dep_context=non-requeueable deps ti=<TaskInstance: Extraçao_de_dados_do_linkedin.Transformaçao_dos_dados manual__2024-03-06T02:22:25.908547+00:00 [queued]>
[2024-03-06T02:22:48.391+0000] {taskinstance.py:1956} INFO - Dependencies all met for dep_context=requeueable deps ti=<TaskInstance: Extraçao_de_dados_do_linkedin.Transformaçao_dos_dados manual__2024-03-06T02:22:25.908547+00:00 [queued]>
[2024-03-06T02:22:48.392+0000] {taskinstance.py:2170} INFO - Starting attempt 1 of 1
[2024-03-06T02:22:48.442+0000] {taskinstance.py:2191} INFO - Executing <Task(PythonOperator): Transformaçao_dos_dados> on 2024-03-06 02:22:25.908547+00:00
[2024-03-06T02:22:48.447+0000] {standard_task_runner.py:60} INFO - Started process 767 to run task
[2024-03-06T02:22:48.450+0000] {standard_task_runner.py:87} INFO - Running: ['***', 'tasks', 'run', 'Extraçao_de_dados_do_linkedin', 'Transformaçao_dos_dados', 'manual__2024-03-06T02:22:25.908547+00:00', '--job-id', '47', '--raw', '--subdir', 'DAGS_FOLDER/dag_exemplo.py', '--cfg-path', '/tmp/tmp1reyhlp7']
[2024-03-06T02:22:48.452+0000] {standard_task_runner.py:88} INFO - Job 47: Subtask Transformaçao_dos_dados
[2024-03-06T02:22:48.527+0000] {task_command.py:423} INFO - Running <TaskInstance: Extraçao_de_dados_do_linkedin.Transformaçao_dos_dados manual__2024-03-06T02:22:25.908547+00:00 [running]> on host 43d6e1a41402
[2024-03-06T02:22:48.863+0000] {taskinstance.py:2480} INFO - Exporting env vars: AIRFLOW_CTX_DAG_OWNER='***' AIRFLOW_CTX_DAG_ID='Extraçao_de_dados_do_linkedin' AIRFLOW_CTX_TASK_ID='Transformaçao_dos_dados' AIRFLOW_CTX_EXECUTION_DATE='2024-03-06T02:22:25.908547+00:00' AIRFLOW_CTX_TRY_NUMBER='1' AIRFLOW_CTX_DAG_RUN_ID='manual__2024-03-06T02:22:25.908547+00:00'
[2024-03-06T02:22:48.898+0000] {taskinstance.py:2698} ERROR - Task failed with exception
Traceback (most recent call last):
  File "/home/airflow/.local/lib/python3.8/site-packages/pandas/io/sql.py", line 2202, in execute
    cur.execute(sql, *args)
sqlite3.OperationalError: no such table: vaga

The above exception was the direct cause of the following exception:

Traceback (most recent call last):
  File "/home/airflow/.local/lib/python3.8/site-packages/airflow/models/taskinstance.py", line 433, in _execute_task
    result = execute_callable(context=context, **execute_callable_kwargs)
  File "/home/airflow/.local/lib/python3.8/site-packages/airflow/operators/python.py", line 199, in execute
    return_value = self.execute_callable()
  File "/home/airflow/.local/lib/python3.8/site-packages/airflow/operators/python.py", line 216, in execute_callable
    return self.python_callable(*self.op_args, **self.op_kwargs)
  File "/opt/airflow/dags/dag_exemplo.py", line 67, in transform_data
    dados = pd.read_sql_query(query, conn)
  File "/home/airflow/.local/lib/python3.8/site-packages/pandas/io/sql.py", line 469, in read_sql_query
    return pandas_sql.read_query(
  File "/home/airflow/.local/lib/python3.8/site-packages/pandas/io/sql.py", line 2266, in read_query
    cursor = self.execute(sql, params)
  File "/home/airflow/.local/lib/python3.8/site-packages/pandas/io/sql.py", line 2214, in execute
    raise ex from exc
pandas.errors.DatabaseError: Execution failed on sql 'SELECT * FROM vaga;': no such table: vaga
[2024-03-06T02:22:48.944+0000] {taskinstance.py:1138} INFO - Marking task as FAILED. dag_id=Extraçao_de_dados_do_linkedin, task_id=Transformaçao_dos_dados, execution_date=20240306T022225, start_date=20240306T022248, end_date=20240306T022248
[2024-03-06T02:22:49.126+0000] {standard_task_runner.py:107} ERROR - Failed to execute job 47 for task Transformaçao_dos_dados (Execution failed on sql 'SELECT * FROM vaga;': no such table: vaga; 767)
[2024-03-06T02:22:49.144+0000] {local_task_job_runner.py:234} INFO - Task exited with return code 1
[2024-03-06T02:22:49.312+0000] {taskinstance.py:3280} INFO - 0 downstream tasks scheduled from follow-on schedule check
