[2024-03-07T04:47:54.278+0000] {taskinstance.py:1956} INFO - Dependencies all met for dep_context=non-requeueable deps ti=<TaskInstance: Extraçao_de_dados_do_linkedin.Extraçao_dos_dados manual__2024-03-07T04:47:52.075370+00:00 [queued]>
[2024-03-07T04:47:54.289+0000] {taskinstance.py:1956} INFO - Dependencies all met for dep_context=requeueable deps ti=<TaskInstance: Extraçao_de_dados_do_linkedin.Extraçao_dos_dados manual__2024-03-07T04:47:52.075370+00:00 [queued]>
[2024-03-07T04:47:54.290+0000] {taskinstance.py:2170} INFO - Starting attempt 1 of 1
[2024-03-07T04:47:54.363+0000] {taskinstance.py:2191} INFO - Executing <Task(PythonOperator): Extraçao_dos_dados> on 2024-03-07 04:47:52.075370+00:00
[2024-03-07T04:47:54.426+0000] {standard_task_runner.py:60} INFO - Started process 6382 to run task
[2024-03-07T04:47:54.428+0000] {standard_task_runner.py:87} INFO - Running: ['***', 'tasks', 'run', 'Extraçao_de_dados_do_linkedin', 'Extraçao_dos_dados', 'manual__2024-03-07T04:47:52.075370+00:00', '--job-id', '100', '--raw', '--subdir', 'DAGS_FOLDER/dag_exemplo.py', '--cfg-path', '/tmp/tmpih4pzad2']
[2024-03-07T04:47:54.431+0000] {standard_task_runner.py:88} INFO - Job 100: Subtask Extraçao_dos_dados
[2024-03-07T04:47:54.703+0000] {task_command.py:423} INFO - Running <TaskInstance: Extraçao_de_dados_do_linkedin.Extraçao_dos_dados manual__2024-03-07T04:47:52.075370+00:00 [running]> on host 4fca1e22de4a
[2024-03-07T04:47:55.241+0000] {taskinstance.py:2480} INFO - Exporting env vars: AIRFLOW_CTX_DAG_OWNER='***' AIRFLOW_CTX_DAG_ID='Extraçao_de_dados_do_linkedin' AIRFLOW_CTX_TASK_ID='Extraçao_dos_dados' AIRFLOW_CTX_EXECUTION_DATE='2024-03-07T04:47:52.075370+00:00' AIRFLOW_CTX_TRY_NUMBER='1' AIRFLOW_CTX_DAG_RUN_ID='manual__2024-03-07T04:47:52.075370+00:00'
[2024-03-07T04:52:38.575+0000] {warnings.py:109} WARNING - /opt/***/dags/scrap/main.py:47: GuessedAtParserWarning: No parser was explicitly specified, so I'm using the best available HTML parser for this system ("lxml"). This usually isn't a problem, but if you run this code on another system, or in a different virtual environment, it may use a different parser and behave differently.

The code that caused this warning is on line 47 of the file /opt/***/dags/scrap/main.py. To get rid of this warning, pass the additional argument 'features="lxml"' to the BeautifulSoup constructor.

  )

[2024-03-07T04:52:38.600+0000] {taskinstance.py:2698} ERROR - Task failed with exception
Traceback (most recent call last):
  File "/home/airflow/.local/lib/python3.8/site-packages/airflow/models/taskinstance.py", line 433, in _execute_task
    result = execute_callable(context=context, **execute_callable_kwargs)
  File "/home/airflow/.local/lib/python3.8/site-packages/airflow/operators/python.py", line 199, in execute
    return_value = self.execute_callable()
  File "/home/airflow/.local/lib/python3.8/site-packages/airflow/operators/python.py", line 216, in execute_callable
    return self.python_callable(*self.op_args, **self.op_kwargs)
  File "/opt/airflow/dags/dag_exemplo.py", line 25, in extract
    test()
  File "/opt/airflow/dags/scrap/main.py", line 220, in test
  File "/opt/airflow/dags/scrap/main.py", line 83, in get_info
    end_page = False
  File "/home/airflow/.local/lib/python3.8/site-packages/selenium/webdriver/remote/webdriver.py", line 741, in find_element
    return self.execute(Command.FIND_ELEMENT, {"using": by, "value": value})["value"]
  File "/home/airflow/.local/lib/python3.8/site-packages/selenium/webdriver/remote/webdriver.py", line 347, in execute
    self.error_handler.check_response(response)
  File "/home/airflow/.local/lib/python3.8/site-packages/selenium/webdriver/remote/errorhandler.py", line 229, in check_response
    raise exception_class(message, screen, stacktrace)
selenium.common.exceptions.NoSuchElementException: Message: Unable to locate element: button.infinite-scroller__show-more-button; For documentation on this error, please visit: https://www.selenium.dev/documentation/webdriver/troubleshooting/errors#no-such-element-exception
Stacktrace:
RemoteError@chrome://remote/content/shared/RemoteError.sys.mjs:8:8
WebDriverError@chrome://remote/content/shared/webdriver/Errors.sys.mjs:191:5
NoSuchElementError@chrome://remote/content/shared/webdriver/Errors.sys.mjs:509:5
dom.find/</<@chrome://remote/content/shared/DOM.sys.mjs:136:16

[2024-03-07T04:52:38.629+0000] {taskinstance.py:1138} INFO - Marking task as FAILED. dag_id=Extraçao_de_dados_do_linkedin, task_id=Extraçao_dos_dados, execution_date=20240307T044752, start_date=20240307T044754, end_date=20240307T045238
[2024-03-07T04:52:38.856+0000] {standard_task_runner.py:107} ERROR - Failed to execute job 100 for task Extraçao_dos_dados (Message: Unable to locate element: button.infinite-scroller__show-more-button; For documentation on this error, please visit: https://www.selenium.dev/documentation/webdriver/troubleshooting/errors#no-such-element-exception
Stacktrace:
RemoteError@chrome://remote/content/shared/RemoteError.sys.mjs:8:8
WebDriverError@chrome://remote/content/shared/webdriver/Errors.sys.mjs:191:5
NoSuchElementError@chrome://remote/content/shared/webdriver/Errors.sys.mjs:509:5
dom.find/</<@chrome://remote/content/shared/DOM.sys.mjs:136:16
; 6382)
[2024-03-07T04:52:38.889+0000] {local_task_job_runner.py:234} INFO - Task exited with return code 1
[2024-03-07T04:52:38.933+0000] {taskinstance.py:3280} INFO - 0 downstream tasks scheduled from follow-on schedule check
