[2024-03-07T03:34:23.872+0000] {taskinstance.py:1956} INFO - Dependencies all met for dep_context=non-requeueable deps ti=<TaskInstance: Extraçao_de_dados_do_linkedin.Extraçao_dos_dados manual__2024-03-07T03:34:21.172963+00:00 [queued]>
[2024-03-07T03:34:23.891+0000] {taskinstance.py:1956} INFO - Dependencies all met for dep_context=requeueable deps ti=<TaskInstance: Extraçao_de_dados_do_linkedin.Extraçao_dos_dados manual__2024-03-07T03:34:21.172963+00:00 [queued]>
[2024-03-07T03:34:23.892+0000] {taskinstance.py:2170} INFO - Starting attempt 1 of 1
[2024-03-07T03:34:23.951+0000] {taskinstance.py:2191} INFO - Executing <Task(PythonOperator): Extraçao_dos_dados> on 2024-03-07 03:34:21.172963+00:00
[2024-03-07T03:34:23.963+0000] {standard_task_runner.py:60} INFO - Started process 5254 to run task
[2024-03-07T03:34:23.966+0000] {standard_task_runner.py:87} INFO - Running: ['***', 'tasks', 'run', 'Extraçao_de_dados_do_linkedin', 'Extraçao_dos_dados', 'manual__2024-03-07T03:34:21.172963+00:00', '--job-id', '81', '--raw', '--subdir', 'DAGS_FOLDER/dag_exemplo.py', '--cfg-path', '/tmp/tmpwx8_rnjp']
[2024-03-07T03:34:23.971+0000] {standard_task_runner.py:88} INFO - Job 81: Subtask Extraçao_dos_dados
[2024-03-07T03:34:24.077+0000] {task_command.py:423} INFO - Running <TaskInstance: Extraçao_de_dados_do_linkedin.Extraçao_dos_dados manual__2024-03-07T03:34:21.172963+00:00 [running]> on host 4fca1e22de4a
[2024-03-07T03:34:24.316+0000] {taskinstance.py:2480} INFO - Exporting env vars: AIRFLOW_CTX_DAG_OWNER='***' AIRFLOW_CTX_DAG_ID='Extraçao_de_dados_do_linkedin' AIRFLOW_CTX_TASK_ID='Extraçao_dos_dados' AIRFLOW_CTX_EXECUTION_DATE='2024-03-07T03:34:21.172963+00:00' AIRFLOW_CTX_TRY_NUMBER='1' AIRFLOW_CTX_DAG_RUN_ID='manual__2024-03-07T03:34:21.172963+00:00'
[2024-03-07T03:34:37.171+0000] {warnings.py:109} WARNING - /opt/***/dags/scrap/main.py:50: GuessedAtParserWarning: No parser was explicitly specified, so I'm using the best available HTML parser for this system ("lxml"). This usually isn't a problem, but if you run this code on another system, or in a different virtual environment, it may use a different parser and behave differently.

The code that caused this warning is on line 50 of the file /opt/***/dags/scrap/main.py. To get rid of this warning, pass the additional argument 'features="lxml"' to the BeautifulSoup constructor.

  soup = BeautifulSoup(data)

[2024-03-07T03:34:47.145+0000] {logging_mixin.py:188} INFO - 25
[2024-03-07T03:34:52.929+0000] {logging_mixin.py:188} INFO - Atualmente na página: 0
[2024-03-07T03:35:02.989+0000] {logging_mixin.py:188} INFO - Loader automático...
[2024-03-07T03:35:09.003+0000] {logging_mixin.py:188} INFO - 25
[2024-03-07T03:35:13.420+0000] {logging_mixin.py:188} INFO - Atualmente na página: 1
[2024-03-07T03:35:23.938+0000] {logging_mixin.py:188} INFO - Loader automático...
[2024-03-07T03:35:29.956+0000] {logging_mixin.py:188} INFO - 50
[2024-03-07T03:35:34.291+0000] {logging_mixin.py:188} INFO - Atualmente na página: 2
[2024-03-07T03:35:44.338+0000] {logging_mixin.py:188} INFO - Loader automático...
[2024-03-07T03:35:50.614+0000] {taskinstance.py:2698} ERROR - Task failed with exception
Traceback (most recent call last):
  File "/opt/airflow/dags/scrap/main.py", line 215, in test
    get_info()
  File "/opt/airflow/dags/scrap/main.py", line 123, in get_info
    title = job.find_element(By.TAG_NAME, "h3").text.strip()
  File "/home/airflow/.local/lib/python3.8/site-packages/selenium/webdriver/remote/webelement.py", line 417, in find_element
    return self._execute(Command.FIND_CHILD_ELEMENT, {"using": by, "value": value})["value"]
  File "/home/airflow/.local/lib/python3.8/site-packages/selenium/webdriver/remote/webelement.py", line 395, in _execute
    return self._parent.execute(command, params)
  File "/home/airflow/.local/lib/python3.8/site-packages/selenium/webdriver/remote/webdriver.py", line 347, in execute
    self.error_handler.check_response(response)
  File "/home/airflow/.local/lib/python3.8/site-packages/selenium/webdriver/remote/errorhandler.py", line 229, in check_response
    raise exception_class(message, screen, stacktrace)
selenium.common.exceptions.InvalidSessionIdException: Message: Tried to run command without establishing a connection


During handling of the above exception, another exception occurred:

Traceback (most recent call last):
  File "/home/airflow/.local/lib/python3.8/site-packages/airflow/models/taskinstance.py", line 433, in _execute_task
    result = execute_callable(context=context, **execute_callable_kwargs)
  File "/home/airflow/.local/lib/python3.8/site-packages/airflow/operators/python.py", line 199, in execute
    return_value = self.execute_callable()
  File "/home/airflow/.local/lib/python3.8/site-packages/airflow/operators/python.py", line 216, in execute_callable
    return self.python_callable(*self.op_args, **self.op_kwargs)
  File "/opt/airflow/dags/dag_exemplo.py", line 25, in extract
    test()
  File "/opt/airflow/dags/scrap/main.py", line 244, in test
    driver.close()
  File "/home/airflow/.local/lib/python3.8/site-packages/selenium/webdriver/remote/webdriver.py", line 458, in close
    self.execute(Command.CLOSE)
  File "/home/airflow/.local/lib/python3.8/site-packages/selenium/webdriver/remote/webdriver.py", line 347, in execute
    self.error_handler.check_response(response)
  File "/home/airflow/.local/lib/python3.8/site-packages/selenium/webdriver/remote/errorhandler.py", line 229, in check_response
    raise exception_class(message, screen, stacktrace)
selenium.common.exceptions.InvalidSessionIdException: Message: Tried to run command without establishing a connection

[2024-03-07T03:35:50.668+0000] {taskinstance.py:1138} INFO - Marking task as FAILED. dag_id=Extraçao_de_dados_do_linkedin, task_id=Extraçao_dos_dados, execution_date=20240307T033421, start_date=20240307T033423, end_date=20240307T033550
[2024-03-07T03:35:50.743+0000] {standard_task_runner.py:107} ERROR - Failed to execute job 81 for task Extraçao_dos_dados (Message: Tried to run command without establishing a connection
; 5254)
[2024-03-07T03:35:50.769+0000] {local_task_job_runner.py:234} INFO - Task exited with return code 1
[2024-03-07T03:35:50.800+0000] {taskinstance.py:3280} INFO - 0 downstream tasks scheduled from follow-on schedule check
