[2024-03-04T19:55:09.315+0000] {taskinstance.py:1956} INFO - Dependencies all met for dep_context=non-requeueable deps ti=<TaskInstance: Extraçao_de_dados_do_linkedin.Extraçao_dos_dados manual__2024-03-04T19:55:07.601683+00:00 [queued]>
[2024-03-04T19:55:09.328+0000] {taskinstance.py:1956} INFO - Dependencies all met for dep_context=requeueable deps ti=<TaskInstance: Extraçao_de_dados_do_linkedin.Extraçao_dos_dados manual__2024-03-04T19:55:07.601683+00:00 [queued]>
[2024-03-04T19:55:09.329+0000] {taskinstance.py:2170} INFO - Starting attempt 1 of 1
[2024-03-04T19:55:09.368+0000] {taskinstance.py:2191} INFO - Executing <Task(PythonOperator): Extraçao_dos_dados> on 2024-03-04 19:55:07.601683+00:00
[2024-03-04T19:55:09.379+0000] {standard_task_runner.py:60} INFO - Started process 243 to run task
[2024-03-04T19:55:09.382+0000] {standard_task_runner.py:87} INFO - Running: ['***', 'tasks', 'run', 'Extraçao_de_dados_do_linkedin', 'Extraçao_dos_dados', 'manual__2024-03-04T19:55:07.601683+00:00', '--job-id', '16', '--raw', '--subdir', 'DAGS_FOLDER/dag_exemplo.py', '--cfg-path', '/tmp/tmps798lmr8']
[2024-03-04T19:55:09.385+0000] {standard_task_runner.py:88} INFO - Job 16: Subtask Extraçao_dos_dados
[2024-03-04T19:55:09.453+0000] {task_command.py:423} INFO - Running <TaskInstance: Extraçao_de_dados_do_linkedin.Extraçao_dos_dados manual__2024-03-04T19:55:07.601683+00:00 [running]> on host 43d6e1a41402
[2024-03-04T19:55:09.758+0000] {taskinstance.py:2480} INFO - Exporting env vars: AIRFLOW_CTX_DAG_OWNER='***' AIRFLOW_CTX_DAG_ID='Extraçao_de_dados_do_linkedin' AIRFLOW_CTX_TASK_ID='Extraçao_dos_dados' AIRFLOW_CTX_EXECUTION_DATE='2024-03-04T19:55:07.601683+00:00' AIRFLOW_CTX_TRY_NUMBER='1' AIRFLOW_CTX_DAG_RUN_ID='manual__2024-03-04T19:55:07.601683+00:00'
[2024-03-04T20:00:01.640+0000] {local_task_job_runner.py:302} WARNING - State of this instance has been externally set to failed. Terminating instance.
[2024-03-04T20:00:01.644+0000] {process_utils.py:131} INFO - Sending 15 to group 243. PIDs of all processes in the group: [244, 245, 246, 243]
[2024-03-04T20:00:01.644+0000] {process_utils.py:86} INFO - Sending the signal 15 to group 243
[2024-03-04T20:00:01.645+0000] {taskinstance.py:2450} ERROR - Received SIGTERM. Terminating subprocesses.
[2024-03-04T20:00:01.672+0000] {process_utils.py:79} INFO - Process psutil.Process(pid=245, status='terminated', started='19:55:09') (245) terminated with exit code None
[2024-03-04T20:00:01.845+0000] {process_utils.py:79} INFO - Process psutil.Process(pid=243, status='terminated', exitcode=0, started='19:55:09') (243) terminated with exit code 0
[2024-03-04T20:00:01.846+0000] {process_utils.py:79} INFO - Process psutil.Process(pid=246, status='terminated', started='19:55:09') (246) terminated with exit code None
[2024-03-04T20:00:01.847+0000] {process_utils.py:79} INFO - Process psutil.Process(pid=244, status='terminated', started='19:55:09') (244) terminated with exit code None
