[2024-03-04T20:02:51.320+0000] {taskinstance.py:1956} INFO - Dependencies all met for dep_context=non-requeueable deps ti=<TaskInstance: Extraçao_de_dados_do_linkedin.Extraçao_dos_dados manual__2024-03-04T20:02:49.468174+00:00 [queued]>
[2024-03-04T20:02:51.329+0000] {taskinstance.py:1956} INFO - Dependencies all met for dep_context=requeueable deps ti=<TaskInstance: Extraçao_de_dados_do_linkedin.Extraçao_dos_dados manual__2024-03-04T20:02:49.468174+00:00 [queued]>
[2024-03-04T20:02:51.330+0000] {taskinstance.py:2170} INFO - Starting attempt 1 of 1
[2024-03-04T20:02:51.391+0000] {taskinstance.py:2191} INFO - Executing <Task(PythonOperator): Extraçao_dos_dados> on 2024-03-04 20:02:49.468174+00:00
[2024-03-04T20:02:51.428+0000] {standard_task_runner.py:60} INFO - Started process 362 to run task
[2024-03-04T20:02:51.431+0000] {standard_task_runner.py:87} INFO - Running: ['***', 'tasks', 'run', 'Extraçao_de_dados_do_linkedin', 'Extraçao_dos_dados', 'manual__2024-03-04T20:02:49.468174+00:00', '--job-id', '17', '--raw', '--subdir', 'DAGS_FOLDER/dag_exemplo.py', '--cfg-path', '/tmp/tmp893ow5qs']
[2024-03-04T20:02:51.433+0000] {standard_task_runner.py:88} INFO - Job 17: Subtask Extraçao_dos_dados
[2024-03-04T20:02:51.525+0000] {task_command.py:423} INFO - Running <TaskInstance: Extraçao_de_dados_do_linkedin.Extraçao_dos_dados manual__2024-03-04T20:02:49.468174+00:00 [running]> on host 43d6e1a41402
[2024-03-04T20:02:51.878+0000] {taskinstance.py:2480} INFO - Exporting env vars: AIRFLOW_CTX_DAG_OWNER='***' AIRFLOW_CTX_DAG_ID='Extraçao_de_dados_do_linkedin' AIRFLOW_CTX_TASK_ID='Extraçao_dos_dados' AIRFLOW_CTX_EXECUTION_DATE='2024-03-04T20:02:49.468174+00:00' AIRFLOW_CTX_TRY_NUMBER='1' AIRFLOW_CTX_DAG_RUN_ID='manual__2024-03-04T20:02:49.468174+00:00'
[2024-03-04T20:02:51.881+0000] {taskinstance.py:2698} ERROR - Task failed with exception
Traceback (most recent call last):
  File "/home/airflow/.local/lib/python3.8/site-packages/airflow/models/taskinstance.py", line 433, in _execute_task
    result = execute_callable(context=context, **execute_callable_kwargs)
  File "/home/airflow/.local/lib/python3.8/site-packages/airflow/operators/python.py", line 199, in execute
    return_value = self.execute_callable()
  File "/home/airflow/.local/lib/python3.8/site-packages/airflow/operators/python.py", line 216, in execute_callable
    return self.python_callable(*self.op_args, **self.op_kwargs)
  File "/opt/airflow/dags/dag_exemplo.py", line 25, in extract_and_save_data
    data = pd.read_csv(source_file)
  File "/home/airflow/.local/lib/python3.8/site-packages/pandas/io/parsers/readers.py", line 912, in read_csv
    return _read(filepath_or_buffer, kwds)
  File "/home/airflow/.local/lib/python3.8/site-packages/pandas/io/parsers/readers.py", line 577, in _read
    parser = TextFileReader(filepath_or_buffer, **kwds)
  File "/home/airflow/.local/lib/python3.8/site-packages/pandas/io/parsers/readers.py", line 1407, in __init__
    self._engine = self._make_engine(f, self.engine)
  File "/home/airflow/.local/lib/python3.8/site-packages/pandas/io/parsers/readers.py", line 1661, in _make_engine
    self.handles = get_handle(
  File "/home/airflow/.local/lib/python3.8/site-packages/pandas/io/common.py", line 859, in get_handle
    handle = open(
FileNotFoundError: [Errno 2] No such file or directory: 'linkedin_jobs.csv'
[2024-03-04T20:02:51.893+0000] {taskinstance.py:1138} INFO - Marking task as FAILED. dag_id=Extraçao_de_dados_do_linkedin, task_id=Extraçao_dos_dados, execution_date=20240304T200249, start_date=20240304T200251, end_date=20240304T200251
[2024-03-04T20:02:51.934+0000] {standard_task_runner.py:107} ERROR - Failed to execute job 17 for task Extraçao_dos_dados ([Errno 2] No such file or directory: 'linkedin_jobs.csv'; 362)
[2024-03-04T20:02:51.965+0000] {local_task_job_runner.py:234} INFO - Task exited with return code 1
[2024-03-04T20:02:51.979+0000] {taskinstance.py:3280} INFO - 0 downstream tasks scheduled from follow-on schedule check
