[2024-03-07T05:42:15.182+0000] {taskinstance.py:1956} INFO - Dependencies all met for dep_context=non-requeueable deps ti=<TaskInstance: Extraçao_de_dados_do_linkedin.Transformaçao_dos_dados manual__2024-03-07T05:34:26.491150+00:00 [queued]>
[2024-03-07T05:42:15.196+0000] {taskinstance.py:1956} INFO - Dependencies all met for dep_context=requeueable deps ti=<TaskInstance: Extraçao_de_dados_do_linkedin.Transformaçao_dos_dados manual__2024-03-07T05:34:26.491150+00:00 [queued]>
[2024-03-07T05:42:15.197+0000] {taskinstance.py:2170} INFO - Starting attempt 1 of 1
[2024-03-07T05:42:15.245+0000] {taskinstance.py:2191} INFO - Executing <Task(PythonOperator): Transformaçao_dos_dados> on 2024-03-07 05:34:26.491150+00:00
[2024-03-07T05:42:15.253+0000] {standard_task_runner.py:60} INFO - Started process 7230 to run task
[2024-03-07T05:42:15.258+0000] {standard_task_runner.py:87} INFO - Running: ['***', 'tasks', 'run', 'Extraçao_de_dados_do_linkedin', 'Transformaçao_dos_dados', 'manual__2024-03-07T05:34:26.491150+00:00', '--job-id', '115', '--raw', '--subdir', 'DAGS_FOLDER/dag_exemplo.py', '--cfg-path', '/tmp/tmpuykfwvjt']
[2024-03-07T05:42:15.260+0000] {standard_task_runner.py:88} INFO - Job 115: Subtask Transformaçao_dos_dados
[2024-03-07T05:42:15.348+0000] {task_command.py:423} INFO - Running <TaskInstance: Extraçao_de_dados_do_linkedin.Transformaçao_dos_dados manual__2024-03-07T05:34:26.491150+00:00 [running]> on host 4fca1e22de4a
[2024-03-07T05:42:15.529+0000] {taskinstance.py:2480} INFO - Exporting env vars: AIRFLOW_CTX_DAG_OWNER='***' AIRFLOW_CTX_DAG_ID='Extraçao_de_dados_do_linkedin' AIRFLOW_CTX_TASK_ID='Transformaçao_dos_dados' AIRFLOW_CTX_EXECUTION_DATE='2024-03-07T05:34:26.491150+00:00' AIRFLOW_CTX_TRY_NUMBER='1' AIRFLOW_CTX_DAG_RUN_ID='manual__2024-03-07T05:34:26.491150+00:00'
[2024-03-07T05:42:15.555+0000] {taskinstance.py:2698} ERROR - Task failed with exception
Traceback (most recent call last):
  File "/home/airflow/.local/lib/python3.8/site-packages/airflow/models/taskinstance.py", line 433, in _execute_task
    result = execute_callable(context=context, **execute_callable_kwargs)
  File "/home/airflow/.local/lib/python3.8/site-packages/airflow/operators/python.py", line 199, in execute
    return_value = self.execute_callable()
  File "/home/airflow/.local/lib/python3.8/site-packages/airflow/operators/python.py", line 216, in execute_callable
    return self.python_callable(*self.op_args, **self.op_kwargs)
  File "/opt/airflow/dags/dag_exemplo.py", line 57, in transform_data
    dados.set_index("id", inplace=True)
  File "/home/airflow/.local/lib/python3.8/site-packages/pandas/core/frame.py", line 5859, in set_index
    raise KeyError(f"None of {missing} are in the columns")
KeyError: "None of ['id'] are in the columns"
[2024-03-07T05:42:15.591+0000] {taskinstance.py:1138} INFO - Marking task as FAILED. dag_id=Extraçao_de_dados_do_linkedin, task_id=Transformaçao_dos_dados, execution_date=20240307T053426, start_date=20240307T054215, end_date=20240307T054215
[2024-03-07T05:42:15.634+0000] {standard_task_runner.py:107} ERROR - Failed to execute job 115 for task Transformaçao_dos_dados ("None of ['id'] are in the columns"; 7230)
[2024-03-07T05:42:15.670+0000] {local_task_job_runner.py:234} INFO - Task exited with return code 1
[2024-03-07T05:42:15.703+0000] {taskinstance.py:3280} INFO - 0 downstream tasks scheduled from follow-on schedule check
